{"trial_id": "0046", "hyperparameters": {"space": [{"class_name": "Int", "config": {"name": "units", "default": null, "conditions": [], "min_value": 32, "max_value": 512, "step": 32, "sampling": "linear"}}, {"class_name": "Float", "config": {"name": "dropout", "default": 0.0, "conditions": [], "min_value": 0.0, "max_value": 0.5, "step": 0.1, "sampling": "linear"}}], "values": {"units": 352, "dropout": 0.0, "tuner/epochs": 17, "tuner/initial_epoch": 6, "tuner/bracket": 3, "tuner/round": 2, "tuner/trial_id": "0036"}}, "metrics": {"metrics": {}}, "score": null, "best_step": 0, "status": "FAILED", "message": "Traceback (most recent call last):\n  File \"/Users/idsg/anaconda3/envs/DAI/lib/python3.12/site-packages/keras_tuner/src/engine/base_tuner.py\", line 274, in _try_run_and_update_trial\n    self._run_and_update_trial(trial, *fit_args, **fit_kwargs)\n  File \"/Users/idsg/anaconda3/envs/DAI/lib/python3.12/site-packages/keras_tuner/src/engine/base_tuner.py\", line 239, in _run_and_update_trial\n    results = self.run_trial(trial, *fit_args, **fit_kwargs)\n              ^^^^^^^^^^^^^^^^^^^^^^^^^^^^^^^^^^^^^^^^^^^^^^\n  File \"/Users/idsg/anaconda3/envs/DAI/lib/python3.12/site-packages/keras_tuner/src/tuners/hyperband.py\", line 427, in run_trial\n    return super().run_trial(trial, *fit_args, **fit_kwargs)\n           ^^^^^^^^^^^^^^^^^^^^^^^^^^^^^^^^^^^^^^^^^^^^^^^^^\n  File \"/Users/idsg/anaconda3/envs/DAI/lib/python3.12/site-packages/keras_tuner/src/engine/tuner.py\", line 314, in run_trial\n    obj_value = self._build_and_fit_model(trial, *args, **copied_kwargs)\n                ^^^^^^^^^^^^^^^^^^^^^^^^^^^^^^^^^^^^^^^^^^^^^^^^^^^^^^^^\n  File \"/Users/idsg/anaconda3/envs/DAI/lib/python3.12/site-packages/keras_tuner/src/engine/tuner.py\", line 233, in _build_and_fit_model\n    results = self.hypermodel.fit(hp, model, *args, **kwargs)\n              ^^^^^^^^^^^^^^^^^^^^^^^^^^^^^^^^^^^^^^^^^^^^^^^\n  File \"/Users/idsg/anaconda3/envs/DAI/lib/python3.12/site-packages/keras_tuner/src/engine/hypermodel.py\", line 149, in fit\n    return model.fit(*args, **kwargs)\n           ^^^^^^^^^^^^^^^^^^^^^^^^^^\n  File \"/Users/idsg/anaconda3/envs/DAI/lib/python3.12/site-packages/keras/src/utils/traceback_utils.py\", line 122, in error_handler\n    raise e.with_traceback(filtered_tb) from None\n  File \"/Users/idsg/anaconda3/envs/DAI/lib/python3.12/site-packages/tensorflow/python/eager/execute.py\", line 59, in quick_execute\n    except TypeError as e:\ntensorflow.python.framework.errors_impl.InvalidArgumentError: Graph execution error:\n\nDetected at node gradient_tape/compile_loss/mean_squared_error/sub/Reshape defined at (most recent call last):\n  File \"<frozen runpy>\", line 198, in _run_module_as_main\n\n  File \"<frozen runpy>\", line 88, in _run_code\n\n  File \"/Users/idsg/anaconda3/envs/DAI/lib/python3.12/site-packages/ipykernel_launcher.py\", line 18, in <module>\n\n  File \"/Users/idsg/anaconda3/envs/DAI/lib/python3.12/site-packages/traitlets/config/application.py\", line 1075, in launch_instance\n\n  File \"/Users/idsg/anaconda3/envs/DAI/lib/python3.12/site-packages/ipykernel/kernelapp.py\", line 739, in start\n\n  File \"/Users/idsg/anaconda3/envs/DAI/lib/python3.12/site-packages/tornado/platform/asyncio.py\", line 205, in start\n\n  File \"/Users/idsg/anaconda3/envs/DAI/lib/python3.12/asyncio/base_events.py\", line 641, in run_forever\n\n  File \"/Users/idsg/anaconda3/envs/DAI/lib/python3.12/asyncio/base_events.py\", line 1986, in _run_once\n\n  File \"/Users/idsg/anaconda3/envs/DAI/lib/python3.12/asyncio/events.py\", line 88, in _run\n\n  File \"/Users/idsg/anaconda3/envs/DAI/lib/python3.12/site-packages/ipykernel/kernelbase.py\", line 545, in dispatch_queue\n\n  File \"/Users/idsg/anaconda3/envs/DAI/lib/python3.12/site-packages/ipykernel/kernelbase.py\", line 534, in process_one\n\n  File \"/Users/idsg/anaconda3/envs/DAI/lib/python3.12/site-packages/ipykernel/kernelbase.py\", line 437, in dispatch_shell\n\n  File \"/Users/idsg/anaconda3/envs/DAI/lib/python3.12/site-packages/ipykernel/ipkernel.py\", line 362, in execute_request\n\n  File \"/Users/idsg/anaconda3/envs/DAI/lib/python3.12/site-packages/ipykernel/kernelbase.py\", line 778, in execute_request\n\n  File \"/Users/idsg/anaconda3/envs/DAI/lib/python3.12/site-packages/ipykernel/ipkernel.py\", line 449, in do_execute\n\n  File \"/Users/idsg/anaconda3/envs/DAI/lib/python3.12/site-packages/ipykernel/zmqshell.py\", line 549, in run_cell\n\n  File \"/Users/idsg/anaconda3/envs/DAI/lib/python3.12/site-packages/IPython/core/interactiveshell.py\", line 3075, in run_cell\n\n  File \"/Users/idsg/anaconda3/envs/DAI/lib/python3.12/site-packages/IPython/core/interactiveshell.py\", line 3130, in _run_cell\n\n  File \"/Users/idsg/anaconda3/envs/DAI/lib/python3.12/site-packages/IPython/core/async_helpers.py\", line 128, in _pseudo_sync_runner\n\n  File \"/Users/idsg/anaconda3/envs/DAI/lib/python3.12/site-packages/IPython/core/interactiveshell.py\", line 3334, in run_cell_async\n\n  File \"/Users/idsg/anaconda3/envs/DAI/lib/python3.12/site-packages/IPython/core/interactiveshell.py\", line 3517, in run_ast_nodes\n\n  File \"/Users/idsg/anaconda3/envs/DAI/lib/python3.12/site-packages/IPython/core/interactiveshell.py\", line 3577, in run_code\n\n  File \"/var/folders/_4/_j38q0cn0kg4pnd1jf3yvymr0000gn/T/ipykernel_3733/1013714081.py\", line 25, in <module>\n\n  File \"/Users/idsg/anaconda3/envs/DAI/lib/python3.12/site-packages/keras_tuner/src/engine/base_tuner.py\", line 234, in search\n\n  File \"/Users/idsg/anaconda3/envs/DAI/lib/python3.12/site-packages/keras_tuner/src/engine/base_tuner.py\", line 274, in _try_run_and_update_trial\n\n  File \"/Users/idsg/anaconda3/envs/DAI/lib/python3.12/site-packages/keras_tuner/src/engine/base_tuner.py\", line 239, in _run_and_update_trial\n\n  File \"/Users/idsg/anaconda3/envs/DAI/lib/python3.12/site-packages/keras_tuner/src/tuners/hyperband.py\", line 427, in run_trial\n\n  File \"/Users/idsg/anaconda3/envs/DAI/lib/python3.12/site-packages/keras_tuner/src/engine/tuner.py\", line 314, in run_trial\n\n  File \"/Users/idsg/anaconda3/envs/DAI/lib/python3.12/site-packages/keras_tuner/src/engine/tuner.py\", line 233, in _build_and_fit_model\n\n  File \"/Users/idsg/anaconda3/envs/DAI/lib/python3.12/site-packages/keras_tuner/src/engine/hypermodel.py\", line 149, in fit\n\n  File \"/Users/idsg/anaconda3/envs/DAI/lib/python3.12/site-packages/keras/src/utils/traceback_utils.py\", line 117, in error_handler\n\n  File \"/Users/idsg/anaconda3/envs/DAI/lib/python3.12/site-packages/keras/src/backend/tensorflow/trainer.py\", line 320, in fit\n\n  File \"/Users/idsg/anaconda3/envs/DAI/lib/python3.12/site-packages/keras/src/backend/tensorflow/trainer.py\", line 121, in one_step_on_iterator\n\n  File \"/Users/idsg/anaconda3/envs/DAI/lib/python3.12/site-packages/keras/src/backend/tensorflow/trainer.py\", line 108, in one_step_on_data\n\n  File \"/Users/idsg/anaconda3/envs/DAI/lib/python3.12/site-packages/keras/src/backend/tensorflow/trainer.py\", line 70, in train_step\n\nInput to reshape is a tensor with 1 values, but the requested shape has 32\n\t [[{{node gradient_tape/compile_loss/mean_squared_error/sub/Reshape}}]] [Op:__inference_one_step_on_iterator_2576882]\n"}